Workbook

Sheet Cuenta Corriente
A1: Serie | C1: Bienes | D1: Servicios | E1: Ingreso primario (Renta factorial) | F1: Ingreso secundario (Transferencias corrientes) | G1: Cuenta corriente | H1: PIB | I1: Cuenta corriente (% PIB)
A2: 2021 | B2: I | C2: -2587.5206 | D2: -1100.5483 | E2: -1867.197 | F2: 2450.1726 | G2: =+C2+D2+E2+F2 -> -3105.0933 | H2: 77009.381 | I2: =+G2/H2 -> -0.040320975
B3: II | C3: -3548.1395 | D3: -1473.5711 | E3: -1652.0671 | F3: 2626.5443 | G3: -4047.2334 | H3: 73783.912 | I3: =+G3/H3 -> -0.054852519
B4: III | C4: -3692.5201 | D4: -1566.1433 | E4: -2339.0876 | F4: 2762.9165 | G4: -4834.8345 | H4: 80312.92 | I4: =+G4/H4 -> -0.060199959
B5: IV | C5: -4155.4611 | D5: -1876.7751 | E5: -2864.9072 | F5: 2934.9017 | G5: -5962.2417 | H5: 86926.558 | I5: =+G5/H5 -> -0.068589414
A6: 2022 | B6: I | C6: -3733.9745 | D6: -1223.555 | E6: -3616.8407 | F6: 3176.4942 | G6: -5397.876 | H6: 86147.8 | I6: =+G6/H6 -> -0.062658316
B7: II | C7: -1974.6221 | D7: -1071.5659 | E7: -4530.5394 | F7: 2828.69 | G7: -4748.0374 | H7: 90433.955 | I7: =+G7/H7 -> -0.052502817
B8: III | C8: -3684.4672 | D8: -731.68315 | E8: -4794.7434 | F8: 3103.6651 | G8: -6107.2287 | H8: 87864.978 | I8: =+G8/H8 -> -0.069506973
B9: IV | C9: -2785.1851 | D9: -888.15882 | E9: -4144.2065 | F9: 3192.6167 | G9: -4624.9337 | H9: 82012.922 | I9: =+G9/H9 -> -0.056392744
A10: 2023 | B10: I | C10: -1917.4467 | D10: -259.52309 | E10: -3727.0918 | F10: 3094.4084 | G10: -2809.6533 | H10: 81206.632 | I10: =+G10/H10 -> -0.034598815
B11: II | C11: -1699.2559 | D11: -357.32718 | E11: -3056.0841 | F11: 3029.1709 | G11: -2083.4963 | H11: 86433.423 | I11: =+G11/H11 -> -0.024105216
B12: III | C12: -1352.9821 | D12: -51.011979 | E12: -3507.7165 | F12: 3364.7879 | G12: -1546.9226 | H12: 99315.849 | I12: =+G12/H12 -> -0.015575788
B13: IV | C13: -1837.8732 | D13: -327.78344 | E13: -3147.8981 | F13: 3433.6791 | G13: -1879.8757 | H13: 102227.49 | I13: =+G13/H13 -> -0.018389141
A14: 2024 | B14: I | C14: -2105.2189 | D14: 323.88717 | E14: -3151.9959 | F14: 3331.0707 | G14: -1602.257 | H14: 102695.24 | I14: =+G14/H14 -> -0.015602056
B15: II | C15: -1967.1972 | D15: -392.33653 | E15: -2964.9696 | F15: 3896.7698 | G15: -1427.7335 | H15: 104491.63 | I15: =+G15/H15 -> -0.013663616
B16: III | C16: -2318.0735 | D16: -62.100235 | E16: -3342.6929 | F16: 4073.2696 | G16: -1649.5971 | H16: 106620.36 | I16: =+G16/H16 -> -0.015471689
B17: IV | C17: -2765.2803 | D17: -396.17023 | E17: -3377.3625 | F17: 4206.0449 | G17: -2332.768 | H17: 106481.51 | I17: =+G17/H17 -> -0.021907729
A18: 2025 | B18: I | C18: -3064.9152 | D18: 515.6094 | E18: -2992.8602 | F18: 3846.2214 | G18: -1695.9447 | H18: 106100.9 | I18: =+G18/H18 -> -0.015984263
B19: II | C19: -3631.8213 | D19: -196.42037 | E19: -2780.2973 | F19: 4150.9926 | G19: -2457.5464 | H19: 105316.26 | I19: =+G19/H19 -> -0.023334919
B20: III | C20: -4007.6606 | D20: -29.361023 | E20: -2993.1171 | F20: 4212.9062 | G20: -2817.2325 | H20: 119185.3 | I20: =+G20/H20 -> -0.023637415
B21: IV | C21: -4128.0567 | D21: -328.84666 | E21: -3679.6806 | F21: 4224.4138 | G21: -3912.1703 | H21: 128262.97 | I21: =+G21/H21 -> -0.030501167
A23: Promedio | C23: =+AVERAGE(C2:C21) -> -2847.8836 | D23: =+AVERAGE(D2:D21) -> -574.66925 | E23: =+AVERAGE(E2:E21) -> -3226.5678 | F23: =+AVERAGE(F2:F21) -> 3396.9868
A24: Mediana | C24: =+MEDIAN(C2:C21) -> -2775.2327 | D24: =+MEDIAN(D2:D21) -> -374.83185 | E24: =+MEDIAN(E2:E21) -> -3149.947 | F24: =+MEDIAN(F2:F21) -> 3261.8437 | I24: =+G20 -> -2817.2325
I25: =+G16 -> -1649.5971
A26: Crecimientos | I26: =+(I24/I25)-1 -> 0.70783067
A27: Serie | I27: =+I24-I25 -> -1167.6354
A28: 2022 | B28: I | C28: =+C6/C2-1 -> 0.44307045 | D28: =+D6/D2-1 -> 0.11176855 | E28: =+E6/E2-1 -> 0.93704293 | F28: =+F6/F2-1 -> 0.29643691
B29: II | C29: =+C7/C3-1 -> -0.44347674 | D29: =+D7/D3-1 -> -0.27281021 | E29: =+E7/E3-1 -> 1.7423459 | F29: =+F7/F3-1 -> 0.076962638
B30: III | C30: =+C8/C4-1 -> -0.0021808672 | D30: =+D8/D4-1 -> -0.53281214 | E30: =+E8/E4-1 -> 1.0498349 | F30: =+F8/F4-1 -> 0.12332929
B31: IV | C31: =+C9/C5-1 -> -0.32975306 | D31: =+D9/D5-1 -> -0.52676332 | E31: =+E9/E5-1 -> 0.44654126 | F31: =+F9/F5-1 -> 0.087810423
A32: 2023 | B32: I | C32: =+C10/C6-1 -> -0.48648639 | D32: =+D10/D6-1 -> -0.78789422 | E32: =+E10/E6-1 -> 0.03048272 | F32: =+F10/F6-1 -> -0.025841635
B33: II | C33: =+C11/C7-1 -> -0.13945261 | D33: =+D11/D7-1 -> -0.66653736 | E33: =+E11/E7-1 -> -0.32544808 | F33: =+F11/F7-1 -> 0.0708741
B34: III | C34: =+C12/C8-1 -> -0.63278759 | D34: =+D12/D8-1 -> -0.93028133 | E34: =+E12/E8-1 -> -0.26842456 | F34: =+F12/F8-1 -> 0.084133706
B35: IV | C35: =+C13/C9-1 -> -0.34012529 | D35: =+D13/D9-1 -> -0.63094051 | E35: =+E13/E9-1 -> -0.24040992 | F35: =+F13/F9-1 -> 0.075506224
A36: 2024 | B36: I | C36: =+C14/C10-1 -> 0.097928213 | D36: =+D14/D10-1 -> -2.2480091 | E36: =+E14/E10-1 -> -0.15430151 | F36: =+F14/F10-1 -> 0.076480621
B37: II | C37: =+C15/C11-1 -> 0.15768151 | D37: =+D15/D11-1 -> 0.09797559 | E37: =+E15/E11-1 -> -0.02981411 | F37: =+F15/F11-1 -> 0.28641464
B38: III | C38: =+C16/C12-1 -> 0.71330692 | D38: =+D16/D12-1 -> 0.21736574 | E38: =+E16/E12-1 -> -0.047045874 | F38: =+F16/F12-1 -> 0.21055762
B39: IV | C39: =+C17/C13-1 -> 0.50460883 | D39: =+D17/D13-1 -> 0.20863407 | E39: =+E17/E13-1 -> 0.072894464 | F39: =+F17/F13-1 -> 0.22493827
A40: 2025 | B40: I | C40: =+C18/C14-1 -> 0.45586536 | D40: =+D18/D14-1 -> 0.59194139 | E40: =+E18/E14-1 -> -0.050487278 | F40: =+F18/F14-1 -> 0.15465019
B41: II | C41: =+C19/C15-1 -> 0.84619081 | D41: =+D19/D15-1 -> -0.49935742 | E41: =+E19/E15-1 -> -0.062284724 | F41: =+F19/F15-1 -> 0.065239375
...

Sheet PIB
A1: Fecha (dd/mm/aaaa) | B1: año | C1: Trimestre | D1: Promedio mensual | F1: año | G1: Trimestre | H1: Promedio trimestral | J1: Fecha (dd/mm/aaaa) | K1: Producto interno bruto Valor (Miles de millones COP) | M1: año | N1: Trimestre | O1: Producto interno bruto Valor (Miles de millones USD)
A2: 43861 | B2: =YEAR(A2) -> 2020 | C2: =INT((MONTH(A2)-1)/3)+1 -> 1 | D2: 3317.37 | F2: 2021 | G2: 1 | H2: =AVERAGEIFS(D:D, B:B, F2, C:C, G2) -> 3554.6533 | J2: 43921 | K2: 266805.95 | M2: 2021 | N2: 1 | O2: =+K6/Tabla5[[#This Row],[Promedio trimestral]]*1000 -> 77009.381
A3: 43890 | B3: =YEAR(A3) -> 2020 | C3: =INT((MONTH(A3)-1)/3)+1 -> 1 | D3: 3408.24 | F3: 2021 | G3: 2 | H3: =AVERAGEIFS(D:D, B:B, F3, C:C, G3) -> 3695.6033 | J3: 44012 | K3: 219874.33 | M3: 2021 | N3: 2 | O3: =+K7/Tabla5[[#This Row],[Promedio trimestral]]*1000 -> 73783.912
A4: 43921 | B4: =YEAR(A4) -> 2020 | C4: =INT((MONTH(A4)-1)/3)+1 -> 1 | D4: 3870.01 | F4: 2021 | G4: 3 | H4: =AVERAGEIFS(D:D, B:B, F4, C:C, G4) -> 3846.7333 | J4: 44104 | K4: 245852.69 | M4: 2021 | N4: 3 | O4: =+K8/Tabla5[[#This Row],[Promedio trimestral]]*1000 -> 80312.92
A5: 43951 | B5: =YEAR(A5) -> 2020 | C5: =INT((MONTH(A5)-1)/3)+1 -> 2 | D5: 3986.56 | F5: 2021 | G5: 4 | H5: =AVERAGEIFS(D:D, B:B, F5, C:C, G5) -> 3879.9867 | J5: 44196 | K5: 265938.03 | M5: 2021 | N5: 4 | O5: =+K9/Tabla5[[#This Row],[Promedio trimestral]]*1000 -> 86926.558
A6: 43982 | B6: =YEAR(A6) -> 2020 | C6: =INT((MONTH(A6)-1)/3)+1 -> 2 | D6: 3863.34 | F6: 2022 | G6: 1 | H6: =AVERAGEIFS(D:D, B:B, F6, C:C, G6) -> 3914.8667 | J6: 44286 | K6: 273741.65 | M6: 2022 | N6: 1 | O6: =+K10/Tabla5[[#This Row],[Promedio trimestral]]*1000 -> 86147.8
A7: 44012 | B7: =YEAR(A7) -> 2020 | C7: =INT((MONTH(A7)-1)/3)+1 -> 2 | D7: 3693 | F7: 2022 | G7: 2 | H7: =AVERAGEIFS(D:D, B:B, F7, C:C, G7) -> 3915.4967 | J7: 44377 | K7: 272676.07 | M7: 2022 | N7: 2 | O7: =+K11/Tabla5[[#This Row],[Promedio trimestral]]*1000 -> 90433.955
A8: 44043 | B8: =YEAR(A8) -> 2020 | C8: =INT((MONTH(A8)-1)/3)+1 -> 3 | D8: 3660.6 | F8: 2022 | G8: 3 | H8: =AVERAGEIFS(D:D, B:B, F8, C:C, G8) -> 4386.03 | J8: 44469 | K8: 308942.39 | M8: 2022 | N8: 3 | O8: =+K12/Tabla5[[#This Row],[Promedio trimestral]]*1000 -> 87864.978
A9: 44074 | B9: =YEAR(A9) -> 2020 | C9: =INT((MONTH(A9)-1)/3)+1 -> 3 | D9: 3788.1 | F9: 2022 | G9: 4 | H9: =AVERAGEIFS(D:D, B:B, F9, C:C, G9) -> 4808.3833 | J9: 44561 | K9: 337273.89 | M9: 2022 | N9: 4 | O9: =+K13/Tabla5[[#This Row],[Promedio trimestral]]*1000 -> 82012.922
A10: 44104 | B10: =YEAR(A10) -> 2020 | C10: =INT((MONTH(A10)-1)/3)+1 -> 3 | D10: 3749.86 | F10: 2023 | G10: 1 | H10: =AVERAGEIFS(D:D, B:B, F10, C:C, G10) -> 4758.63 | J10: 44651 | K10: 337257.15 | M10: 2023 | N10: 1 | O10: =+K14/Tabla5[[#This Row],[Promedio trimestral]]*1000 -> 81206.632
A11: 44135 | B11: =YEAR(A11) -> 2020 | C11: =INT((MONTH(A11)-1)/3)+1 -> 4 | D11: 3833.06 | F11: 2023 | G11: 2 | H11: =AVERAGEIFS(D:D, B:B, F11, C:C, G11) -> 4426.3667 | J11: 44742 | K11: 354093.85 | M11: 2023 | N11: 2 | O11: =+K15/Tabla5[[#This Row],[Promedio trimestral]]*1000 -> 86433.423
A12: 44165 | B12: =YEAR(A12) -> 2020 | C12: =INT((MONTH(A12)-1)/3)+1 -> 4 | D12: 3680.67 | F12: 2023 | G12: 3 | H12: =AVERAGEIFS(D:D, B:B, F12, C:C, G12) -> 4047.6367 | J12: 44834 | K12: 385378.43 | M12: 2023 | N12: 3 | O12: =+K16/Tabla5[[#This Row],[Promedio trimestral]]*1000 -> 99315.849
A13: 44196 | B13: =YEAR(A13) -> 2020 | C13: =INT((MONTH(A13)-1)/3)+1 -> 4 | D13: 3468.5 | F13: 2023 | G13: 4 | H13: =AVERAGEIFS(D:D, B:B, F13, C:C, G13) -> 4071.1867 | J13: 44926 | K13: 394349.57 | M13: 2023 | N13: 4 | O13: =+K17/Tabla5[[#This Row],[Promedio trimestral]]*1000 -> 102227.49
... A21: 44439 | B21: =YEAR(A21) -> 2021 | C21: =INT((MONTH(A21)-1)/3)+1 -> 3 | D21: 3887.68 | F21: 2025 | G21: 4 | H21: =AVERAGEIFS(D:D, B:B, F21, C:C, G21) -> 3818.9033 | J21: 45657 | K21: 463374.87 | M21: 2025 | N21: 4 | O21: =+K25/Tabla5[[#This Row],[Promedio trimestral]]*1000 -> 128262.97
A22: 44469 | B22: =YEAR(A22) -> 2021 | C22: =INT((MONTH(A22)-1)/3)+1 -> 3 | D22: 3820.28 | F22: 2026 | G22: 1 | H22: =AVERAGEIFS(D:D, B:B, F22, C:C, G22) -> 3695.9233 | J22: 45747 | K22: 444412.11
A23: 44500 | B23: =YEAR(A23) -> 2021 | C23: =INT((MONTH(A23)-1)/3)+1 -> 4 | D23: 3771.68 | J23: 45838 | K23: 442049.55
A24: 44530 | B24: =YEAR(A24) -> 2021 | C24: =INT((MONTH(A24)-1)/3)+1 -> 4 | D24: 3900.51 | J24: 45930 | K24: 477659.73
A25: 44561 | B25: =YEAR(A25) -> 2021 | C25: =INT((MONTH(A25)-1)/3)+1 -> 4 | D25: 3967.77 | J25: 46022 | K25: 489823.88
A26: 44592 | B26: =YEAR(A26) -> 2022 | C26: =INT((MONTH(A26)-1)/3)+1 -> 1 | D26: 4000.72
A27: 44620 | B27: =YEAR(A27) -> 2022 | C27: =INT((MONTH(A27)-1)/3)+1 -> 1 | D27: 3938.36
A28: 44651 | B28: =YEAR(A28) -> 2022 | C28: =INT((MONTH(A28)-1)/3)+1 -> 1 | D28: 3805.52
A29: 44681 | B29: =YEAR(A29) -> 2022 | C29: =INT((MONTH(A29)-1)/3)+1 -> 2 | D29: 3796.39 | K29: 279339 | M29: 279339 | N29: 273741.65 | O29: 273741.65
A30: 44712 | B30: =YEAR(A30) -> 2022 | C30: =INT((MONTH(A30)-1)/3)+1 -> 2 | D30: 4027.6 | K30: 281883.7 | M30: 281883.7 | N30: 272676.07 | O30: 272676.07
A31: 44742 | B31: =YEAR(A31) -> 2022 | C31: =INT((MONTH(A31)-1)/3)+1 -> 2 | D31: 3922.5 | K31: 305608.79 | M31: 305608.79 | N31: 308942.39 | O31: 308942.39
A32: 44773 | B32: =YEAR(A32) -> 2022 | C32: =INT((MONTH(A32)-1)/3)+1 -> 3 | D32: 4394.01 | K32: 325802.51 | M32: 325802.51 | N32: 337273.89 | O32: 337273.89
A33: 44804 | B33: =YEAR(A33) -> 2022 | C33: =INT((MONTH(A33)-1)/3)+1 -> 3 | D33: 4326.77 | K33: 343812.22 | M33: 343812.22 | N33: 337257.15 | O33: 337257.15
A34: 44834 | B34: =YEAR(A34) -> 2022 | C34: =INT((MONTH(A34)-1)/3)+1 -> 3 | D34: 4437.31 | K34: 365869.86 | M34: 365869.86 | N34: 354093.85 | O34: 354093.85
A35: 44865 | B35: =YEAR(A35) -> 2022 | C35: =INT((MONTH(A35)-1)/3)+1 -> 4 | D35: 4714.96 | K35: 380784.65 | M35: 380784.65 | N35: 385378.43 | O35: 385378.43
A36: 44895 | B36: =YEAR(A36) -> 2022 | C36: =INT((MONTH(A36)-1)/3)+1 -> 4 | D36: 4922.3 | K36: 380612.27 | M36: 380612.27 | N36: 394349.57 | O36: 394349.57
A37: 44926 | B37: =YEAR(A37) -> 2022 | C37: =INT((MONTH(A37)-1)/3)+1 -> 4 | D37: 4787.89 | K37: 393577.25 | M37: 393577.25 | N37: 386432.32 | O37: 386432.32
A38: 44957 | B38: =YEAR(A38) -> 2023 | C38: =INT((MONTH(A38)-1)/3)+1 -> 1 | D38: 4712.18 | K38: 395046.8 | M38: 395046.8 | N38: 382586.02 | O38: 382586.02
A39: 44985 | B39: =YEAR(A39) -> 2023 | C39: =INT((MONTH(A39)-1)/3)+1 -> 1 | D39: 4802.75 | K39: 396686.48 | M39: 396686.48 | N39: 401994.47 | O39: 401994.47
A40: 45016 | B40: =YEAR(A40) -> 2023 | C40: =INT((MONTH(A40)-1)/3)+1 -> 1 | D40: 4760.96 | K40: 401889.47 | M40: 401889.47 | N40: 416187.19 | O40: 416187.19
... A48: 45260 | B48: =YEAR(A48) -> 2023 | C48: =INT((MONTH(A48)-1)/3)+1 -> 4 | D48: 4040.26 | K48: 473028.86 | M48: 473028.86 | N48: 489823.88 | O48: 489823.88
A49: 45291 | B49: =YEAR(A49) -> 2023 | C49: =INT((MONTH(A49)-1)/3)+1 -> 4 | D49: 3954.14
A50: 45322 | B50: =YEAR(A50) -> 2024 | C50: =INT((MONTH(A50)-1)/3)+1 -> 1 | D50: 3920.2
A51: 45351 | B51: =YEAR(A51) -> 2024 | C51: =INT((MONTH(A51)-1)/3)+1 -> 1 | D51: 3931.85
A52: 45382 | B52: =YEAR(A52) -> 2024 | C52: =INT((MONTH(A52)-1)/3)+1 -> 1 | D52: 3908.67
A53: 45412 | B53: =YEAR(A53) -> 2024 | C53: =INT((MONTH(A53)-1)/3)+1 -> 2 | D53: 3866.12
A54: 45443 | B54: =YEAR(A54) -> 2024 | C54: =INT((MONTH(A54)-1)/3)+1 -> 2 | D54: 3865.09
...

Sheet Cuenta Financiera 
A1: Serie | C1: Inversión Directa | D1: Inversión de Cartera | E1: Derivados Financieros | F1: Otra Inversión | G1: Activos de Reserva | H1: Cuenta Financiera | I1: PIB | J1: Cuenta Financiera (% PIB)
A2: 2021 | B2: I | C2: -1438.1448 | D2: 1318.8281 | E2: -320.8628 | F2: -2538.9623 | G2: 190.12769 | H2: -2789.0142 | I2: 77009.381 | J2: =+H2/I2 -> -0.036216551
B3: II | C3: -1012.6176 | D3: -6089.3847 | E3: 181.65367 | F3: 2985.7917 | G3: 173.98878 | H3: -3760.5681 | I3: 73783.912 | J3: =+H3/I3 -> -0.050967318
B4: III | C4: -2527.8876 | D4: 850.56586 | E4: 356.06059 | F4: -3336.9983 | G4: 154.45625 | H4: -4503.8032 | I4: 80312.92 | J4: =+H4/I4 -> -0.05607819
B5: IV | C5: -1401.8715 | D5: -675.38217 | E5: 148.30763 | F5: -3845.7681 | G5: 134.97245 | H5: -5639.7417 | I5: 86926.558 | J5: =+H5/I5 -> -0.064879386
A6: 2022 | B6: I | C6: -3650.5735 | D6: 1865.9168 | E6: -377.13608 | F6: -3001.8772 | G6: 126.94617 | H6: -5036.7239 | I6: 86147.8 | J6: =+H6/I6 -> -0.058466076
B7: II | C7: -3660.5871 | D7: -759.03032 | E7: 36.169823 | F7: -642.40142 | G7: 74.078561 | H7: -4951.7705 | I7: 90433.955 | J7: =+H7/I7 -> -0.054755655
B8: III | C8: -2958.9114 | D8: -233.03539 | E8: 487.33717 | F8: -3190.5331 | G8: 159.38366 | H8: -5735.759 | I8: 87864.978 | J8: =+H8/I8 -> -0.06527924
B9: IV | C9: -3528.6486 | D9: -446.84973 | E9: 676.96965 | F9: -1653.3629 | G9: 210.4825 | H9: -4741.4091 | I9: 82012.922 | J9: =+H9/I9 -> -0.057812951
A10: 2023 | B10: I | C10: -3600.4136 | D10: 1111.281 | E10: -248.37005 | F10: -218.92539 | G10: 365.72012 | H10: -2590.708 | I10: 81206.632 | J10: =+H10/I10 -> -0.031902665
B11: II | C11: -5441.7419 | D11: 1519.8079 | E11: -756.289 | F11: 1579.9865 | G11: 399.08936 | H11: -2699.1472 | I11: 86433.423 | J11: =+H11/I11 -> -0.031228049
B12: III | C12: -3334.7106 | D12: 4527.3295 | E12: -690.52363 | F12: -2335.7995 | G12: 457.47195 | H12: -1376.2322 | I12: 99315.849 | J12: =+H12/I12 -> -0.013857126
B13: IV | C13: -3148.0399 | D13: 1504.3073 | E13: -879.40545 | F13: 844.61255 | G13: 496.10653 | H13: -1182.4189 | I13: 102227.49 | J13: =+H13/I13 -> -0.011566546
A14: 2024 | B14: I | C14: -2407.8679 | D14: 1415.8371 | E14: -575.17205 | F14: -869.8318 | G14: 951.37463 | H14: -1485.66 | I14: 102695.24 | J14: =+H14/I14 -> -0.014466687
B15: II | C15: -1646.381 | D15: -451.25025 | E15: 80.169823 | F15: 23.453203 | G15: 914.45395 | H15: -1079.5542 | I15: 104491.63 | J15: =+H15/I15 -> -0.01033149
B16: III | C16: -2455.6267 | D16: 3489.4302 | E16: 281.66982 | F16: -3385.3811 | G16: 1045.5225 | H16: -1024.3852 | I16: 106620.36 | J16: =+H16/I16 -> -0.0096077822
B17: IV | C17: -2662.2075 | D17: -2182.4411 | E17: 156.66982 | F17: 2018.3096 | G17: 681.96286 | H17: -1987.7062 | I17: 106481.51 | J17: =+H17/I17 -> -0.018667149
A18: 2025 | B18: I | C18: -2127.9738 | D18: 2941.0469 | E18: -422.28289 | F18: -2429.2437 | G18: 563.57735 | H18: -1474.8761 | I18: 106100.9 | J18: =+H18/I18 -> -0.013900693
B19: II | C19: -1561.2484 | D19: -3760.1065 | E19: -448.3182 | F19: 3394.6394 | G19: 524.5847 | H19: -1850.4489 | I19: 105316.26 | J19: =+H19/I19 -> -0.017570401
B20: III | C20: -1858.9646 | D20: -4963.3956 | E20: -398.30489 | F20: 4435.3334 | G20: 534.1645 | H20: -2251.1671 | I20: 119185.3 | J20: =+H20/I20 -> -0.018887959
B21: IV | C21: -1761.7596 | D21: -1697.9149 | E21: -438.52609 | F21: -115.63938 | G21: 542.91345 | H21: -3470.9265 | I21: 128262.97 | J21: =+H21/I21 -> -0.027061018
A24: Promedio | C24: =AVERAGE(C2:C21) -> -2609.3089 | D24: =AVERAGE(D2:D21) -> -35.721994 | E24: =AVERAGE(E2:E21) -> -157.50916 | F24: =AVERAGE(F2:F21) -> -614.12989 | G24: =AVERAGE(G2:G21) -> 435.0689 | H24: =AVERAGE(H2:H21) -> -2981.601
A25: Mediana | C25: =MEDIAN(C2:C21) -> -2491.7571 | D25: =MEDIAN(D2:D21) -> 308.76524 | E25: =MEDIAN(E2:E21) -> -284.61643 | F25: =MEDIAN(F2:F21) -> -756.11661 | G25: =MEDIAN(G2:G21) -> 428.28065 | H25: =MEDIAN(H2:H21) -> -2644.9276
A27: Crecimientos
A28: Serie
A29: 2022 | B29: I | C29: =(C6/C2)-1 -> 1.5383908 | D29: =(D6/D2)-1 -> 0.41482947 | E29: =(E6/E2)-1 -> 0.17538112 | F29: =(F6/F2)-1 -> 0.18232444
B30: II | C30: =(C7/C3)-1 -> 2.6149748 | D30: =(D7/D3)-1 -> -0.87535189 | E30: =(E7/E3)-1 -> -0.80088581 | F30: =(F7/F3)-1 -> -1.2151528
B31: III | C31: =(C8/C4)-1 -> 0.17050749 | D31: =(D8/D4)-1 -> -1.2739769 | E31: =(E8/E4)-1 -> 0.36869171 | F31: =(F8/F4)-1 -> -0.043891292
B32: IV | C32: =(C9/C5)-1 -> 1.5170984 | D32: =(D9/D5)-1 -> -0.33837501 | E32: =(E9/E5)-1 -> 3.5646312 | F32: =(F9/F5)-1 -> -0.57008254
A33: 2023 | B33: I | C33: =(C10/C6)-1 -> -0.013740278 | D33: =(D10/D6)-1 -> -0.40443167 | E33: =(E10/E6)-1 -> -0.3414312 | F33: =(F10/F6)-1 -> -0.9270705
B34: II | C34: =(C11/C7)-1 -> 0.48657627 | D34: =(D11/D7)-1 -> -3.0023019 | E34: =(E11/E7)-1 -> -21.909392 | F34: =(F11/F7)-1 -> -3.4595003
B35: III | C35: =(C12/C8)-1 -> 0.12700591 | D35: =(D12/D8)-1 -> -20.427648 | E35: =(E12/E8)-1 -> -2.416932 | F35: =(F12/F8)-1 -> -0.26789682
B36: IV | C36: =(C13/C9)-1 -> -0.10786247 | D36: =(D13/D9)-1 -> -4.3664726 | E36: =(E13/E9)-1 -> -2.2990323 | F36: =(F13/F9)-1 -> -1.5108452
A37: 2024 | B37: I | C37: =(C14/C10)-1 -> -0.33122465 | D37: =(D14/D10)-1 -> 0.27405866 | E37: =(E14/E10)-1 -> 1.3157866 | F37: =(F14/F10)-1 -> 2.9731883
B38: II | C38: =(C15/C11)-1 -> -0.69745332 | D38: =(D15/D11)-1 -> -1.2969127 | E38: =(E15/E11)-1 -> -1.1060042 | F38: =(F15/F11)-1 -> -0.98515607
B39: III | C39: =(C16/C12)-1 -> -0.26361625 | D39: =(D16/D12)-1 -> -0.22925198 | E39: =(E16/E12)-1 -> -1.4079076 | F39: =(F16/F12)-1 -> 0.44934579
B40: IV | C40: =(C17/C13)-1 -> -0.15432855 | D40: =(D17/D13)-1 -> -2.4507947 | E40: =(E17/E13)-1 -> -1.1781543 | F40: =(F17/F13)-1 -> 1.3896278
A41: 2025 | B41: I | C41: =(C18/C14)-1 -> -0.11624148 | D41: =(D18/D14)-1 -> 1.0772495 | E41: =(E18/E14)-1 -> -0.26581465 | F41: =(F18/F14)-1 -> 1.7927741
B42: II | C42: =(C19/C15)-1 -> -0.051708908 | D42: =(D19/D15)-1 -> 7.3326413 | E42: =(E19/E15)-1 -> -6.5921066 | F42: =(F19/F15)-1 -> 143.74098

Sheet Participación Exportaciones
D1: 1 | E1: 2 | F1: 3 | G1: 4 | H1: 5 | I1: 6 | J1: 7 | K1: 8 | L1: 9 | M1: 10 | N1: 11 | O1: 12 | P1: 13 | Q1: 14 | R1: 15 | S1: 16 | T1: 17 | U1: 18 | V1: 19 | W1: 20 | X1: 21 | Y1: 22 | Z1: 23 | AA1: 24 | AB1: 25 | AC1: 26 | AD1: 27 | AE1: 28 | AF1: 29 | AG1: 30 | AH1: 31 | AI1: 32 | AJ1: 33 | AK1: 34 | AL1: 35 | AM1: 36 | AN1: 37 | AO1: 38 | AP1: 39 | AQ1: 40 | AR1: 41 | AS1: 42 | AT1: 43 | AU1: 44 | AV1: 45 | AW1: 46 | AX1: 47 | AY1: 48 | AZ1: 49 | BA1: 50 | BB1: 51 | BC1: 52 | BD1: 53 | BE1: 54 | BF1: 55 | BG1: 56 | BH1: 57 | BI1: 58 | BJ1: 59 | BK1: 60 | BL1: 61 | BM1: 62 | BN1: 63 | BO1: 64 | BP1: 65 | BQ1: 66 | BR1: 67 | BS1: 68 | BT1: 69 | BU1: 70 | BV1: 71 | BW1: 72 | BX1: 73 | BY1: 74 | BZ1: 75 | CA1: 76 | CB1: 78 | CC1: 79 | CD1: 80 | CE1: 81 | CF1: 82 | CG1: 83 | CH1: 84 | CI1: 85 | CJ1: 86 | CK1: 87 | CL1: 88 | CM1: 89 | CN1: 90 | CO1: 91 | CP1: 92 | CQ1: 93 | CR1: 94 | CS1: 95 | CT1: 96 | CU1: 97 | CV1: 98 | CW1: Total exportaciones
D2: Animales vivos | E2: Carnes y despojos comestibles | F2: Pescados y crustáceos, moluscos e invertebrados acuáticos | G2: Leche y productos lácteos, huevos, miel | H2: Demás productos de origen animal | I2: Plantas vivas y productos de la floricultura | J2: Legumbres y hortalizas, plantas, raíces y tubérculos | K2: Frutos comestibles, cortezas de agrios o melones | L2: Café, té, yerba mate y especias | M2: Cereales | N2: Productos de molinería, malta, almidón y fécula | O2: Semillas y frutos oleaginosos, forrajes | P2: Gomas, resinas, y demás jugos y extractos vegetales | Q2: Materias trenzables y demás productos vegetales | R2: Grasas y aceites animales o vegetales | S2: Preparaciones de carne, pescado, crustáceos, moluscos | T2: Azúcares y artículos confitería | U2: Cacao y sus preparaciones | V2: Preparaciones a base de cereal, harina, leche; pastelería | W2: Preparaciones de legumbres u hortalizas, frutos, otras | X2: Preparaciones alimenticias diversas | Y2: Bebidas, líquidos alcohólicos y vinagre | Z2: Residuos industrias alimentarias. Alimentos para animales | AA2: Tabaco, sucedáneos del tabaco elaborados | AB2: Sal; azufre; tierras y piedras; yesos, cales y cementos | AC2: Minerales, escorias y cenizas | AD2: Combustibles y aceites minerales y sus productos | AE2: Productos químicos inorgánicos | AF2: Productos químicos orgánicos | AG2: Productos farmacéuticos | AH2: Abonos | AI2: Extractos curtientes, pinturas, tintas | AJ2: Aceites esenciales, perfumería, cosméticos | AK2: Jabones, ceras artificiales, pastas | AL2: Materias albuminoideas, colas | AM2: Pólvoras, explosivos, fósforos | AN2: Productos fotográficos, cinematográficos | AO2: Productos diversos de las industrias químicas | AP2: Materias plásticas y manufacturas | AQ2: Caucho y manufacturas | AR2: Pieles y cueros | AS2: Manufacturas de cuero, artículos de viaje, bolsos | AT2: Peletería y confecciones | AU2: Madera, carbón vegetal y manufacturas de madera | AV2: Corcho y sus manufacturas | AW2: Manufactura de espartería y cestería | AX2: Pastas de madera, desperdicios de papel o cartón | AY2: Papel, cartón y sus manufacturas | AZ2: Productos editoriales, prensa, textos | BA2: Seda | BB2: Lana y pelo fino u ordinario; hilados y tejidos de crin | BC2: Algodón | BD2: Demás fibras vegetales, hilados de papel | BE2: Filamentos sintéticos o artificiales | BF2: Fibras sintéticas o artificiales discontinuas | BG2: Guata, fieltro y telas sin tejer; cordeles ,cuerdas, cordajes | BH2: Alfombras y materias textiles | BI2: Tejidos especiales, superficies textiles con pelo | BJ2: Tejidos impregnados, recubiertos | BK2: Tejidos de punto | BL2: Prendas y complementos de vestir, de punto | BM2: Prendas y complementos de vestir, excepto de punto | BN2: Demás artículos textiles confeccionados | BO2: Calzado, botines, artículos análogos y partes | BP2: Artículos de sombrerería y partes | BQ2: Paraguas, bastones, látigos y sus partes | BR2: Plumas, flores artificiales; manufactura de cabellos | BS2: Manufacturas de piedra, yeso, cemento, mica y análogas | BT2: Productos cerámicos | BU2: Vidrio y manufacturas | BV2: Perlas finas, piedras y metales preciosos | BW2: Fundición, hierro y acero | BX2: Manufactura de fundición, de hierro o acero | BY2: Cobre y sus manufacturas | BZ2: Níquel y sus manufacturas | CA2: Aluminio y sus manufacturas | CB2: Plomo y manufacturas | CC2: Zinc y manufacturas | CD2: Estaño y manufacturas | CE2: Demás metales comunes, "cermets" y manufacturas | CF2: Herramientas y útiles, cuchillería y cubiertos | CG2: Manufacturas diversas de metales comunes | CH2: Reactores nucleares, calderas, máquinas y partes | CI2: Aparatos y material eléctrico, de grabación o imagen | CJ2: Vehículos y material para vía férrea, aparatos de señalización | CK2: Vehículos automóviles, tractores, ciclos, partes y accesorios | CL2: Navegación aérea o espacial | CM2: Navegación marítima o fluvial | CN2: Instrumentos y aparatos de óptica, fotografía, cinematografía | CO2: Relojería | CP2: Instrumentos de música, partes y accesorios | CQ2: Armas y municiones, sus partes y accesorios | CR2: Muebles | CS2: Juguetes, artículos para recreo, deporte; partes y accesorios | CT2: Manufacturas diversas | CU2: Objetos de arte, de colección o de antigüedad | CV2: Disposiciones de tratamiento especial
A3: 2020 | B3: =ROUNDUP(MONTH($B3)/3, 0) -> 1 | C3: 43831 | D3: 6122.9003 | E3: 7236.148 | F3: 11585.546 | G3: 680.37512 | H3: 2954.1104 | I3: 98100.147 | J3: 2331.0486 | K3: 143866.28 | L3: 249836.31 | M3: 964.12477 | N3: 2633.421 | O3: 3537.8468 | P3: 1298.8281 | Q3: 18.5356 | R3: 38748.95 | S3: 2188.4464 | T3: 40663.19 | U3: 8592.5171 | V3: 10371.43 | W3: 7294.9357 | X3: 26189.791 | Y3: 3066.0825 | Z3: 2913.4527 | AA3: 939.43288 | AB3: 1114.8014 | AC3: 13152.438 | AD3: 2043776.8 | AE3: 8156.1252 | AF3: 6790.1305 | AG3: 29049.362 | AH3: 2803.1585 | AI3: 7080.6298 | AJ3: 34016.233 | AK3: 11667.095 | AL3: 4931.6327 | AM3: 46.9025 | AN3: 6.66746 | AO3: 32286.053 | AP3: 100590.09 | AQ3: 8135.9011 | AR3: 1970.6104 | AS3: 3227.3267 | AT3: 401.41898 | AU3: 3888.593 | AV3: 12.31539 | AW3: 31.44041 | AX3: 11.48123 | AY3: 17665.058 | AZ3: 2995.6465 | BA3: 0 | BB3: 0 | BC3: 1383.4871 | BD3: 64.64511 | BE3: 3481.7337 | BF3: 636.4096 | BG3: 468.10363 | BH3: 29.35186 | BI3: 818.93093 | BJ3: 2272.6412 | BK3: 3957.574 | BL3: 12350.538 | BM3: 14497.092 | BN3: 4885.2416 | BO3: 1618.684 | BP3: 217.94904 | BQ3: 14.96882 | BR3: 0.08604 | BS3: 3592.5515 | BT3: 6114.6121 | BU3: 14219.861 | BV3: 116520.24 | BW3: 43551.952 | BX3: 20879.461 | BY3: 15277.688 | BZ3: 16.75106 | CA3: 20060.531 | CB3: 677.09234 | CC3: 24.70053 | CD3: 8.66622 | CE3: 117.58025 | CF3: 3260.5309 | CG3: 1947.4418 | CH3: 28480.795 | CI3: 34736.171 | CJ3: 26.724 | CK3: 28659.644 | CL3: 1386.4291 | CM3: 29.292 | CN3: 6846.3876 | CO3: 78.97624 | CP3: 0.15017 | CQ3: 52.35165 | CR3: 8875.4384 | CS3: 1672.9645 | CT3: 8823.2392 | CU3: 266.02392 | CV3: 622.23346 | CW3: 3419465.6 | CX3: 3419465.6
A4: 2020 | B4: =ROUNDUP(MONTH($B4)/3, 0) -> 1 | C4: 43862 | D4: 7431.8957 | E4: 9251.6271 | F4: 9498.1699 | G4: 796.68879 | H4: 2423.1888 | I4: 180000.25 | J4: 1953.9865 | K4: 101524.52 | L4: 215605.59 | M4: 15.68003 | N4: 6125.2962 | O4: 2455.8284 | P4: 31.67113 | Q4: 32.58348 | R4: 42627.233 | S4: 1135.9352 | T4: 35424.314 | U4: 8577.5093 | V4: 11517.871 | W4: 9077.7886 | X4: 25901.521 | Y4: 1550.9687 | Z4: 2649.9762 | AA4: 1858.3649 | AB4: 1431.9641 | AC4: 1682.495 | AD4: 1483145.6 | AE4: 7681.4076 | AF4: 6486.9171 | AG4: 23261.158 | AH4: 2773.3533 | AI4: 6845.4544 | AJ4: 38373.277 | AK4: 12773.048 | AL4: 3401.0881 | AM4: 0 | AN4: 31.15843 | AO4: 33745.061 | AP4: 116884.19 | AQ4: 7590.4103 | AR4: 3810.38 | AS4: 4333.2467 | AT4: 542.10329 | AU4: 4564.3174 | AV4: 1.9762 | AW4: 50.05919 | AX4: 153.56825 | AY4: 19458.613 | AZ4: 3605.4033 | BA4: 0 | BB4: 0 | BC4: 1132.0142 | BD4: 123.12639 | BE4: 4088.8184 | BF4: 785.10321 | BG4: 500.05634 | BH4: 36.19873 | BI4: 1255.6574 | BJ4: 2925.2557 | BK4: 4090.1692 | BL4: 13397.588 | BM4: 21135.42 | BN4: 8245.1037 | BO4: 2158.0515 | BP4: 460.4772 | BQ4: 167.35914 | BR4: 10.039 | BS4: 3476.2636 | BT4: 5146.6372 | BU4: 9790.6223 | BV4: 191257.56 | BW4: 4711.4294 | BX4: 12461.115 | BY4: 14635.269 | BZ4: 63.96277 | CA4: 24250.607 | CB4: 742.3143 | CC4: 56.49317 | CD4: 12.56253 | CE4: 124.89492 | CF4: 3852.4969 | CG4: 1876.0374 | CH4: 34905.922 | CI4: 43112.747 | CJ4: 27.761 | CK4: 37511.541 | CL4: 1238.4834 | CM4: 122.72347 | CN4: 8400.3097 | CO4: 52.76473 | CP4: 129.83285 | CQ4: 685.89422 | CR4: 11079.723 | CS4: 1331.0455 | CT4: 10428.054 | CU4: 979.719 | CV4: 555.87673 | CW4: 2943625.8 | CX4: 2943625.8
A5: 2020 | B5: =ROUNDUP(MONTH($B5)/3, 0) -> 1 | C5: 43891 | D5: 18809.798 | E5: 9672.7281 | F5: 5698.4683 | G5: 842.78521 | H5: 3408.1068 | I5: 154802.75 | J5: 2702.951 | K5: 99170.293 | L5: 170321.53 | M5: 791.77326 | N5: 4971.5231 | O5: 2865.5421 | P5: 65.7425 | Q5: 40.60808 | R5: 51135.688 | S5: 1633.2407 | T5: 43779.437 | U5: 10806.655 | V5: 11366.99 | W5: 8291.3173 | X5: 28675.154 | Y5: 1786.1461 | Z5: 3114.1836 | AA5: 939.73532 | AB5: 1390.0653 | AC5: 2568.1071 | AD5: 950857.23 | AE5: 7399.9066 | AF5: 10273.921 | AG5: 25861.58 | AH5: 3378.9237 | AI5: 8777.3787 | AJ5: 38702.422 | AK5: 14495.834 | AL5: 4735.4691 | AM5: 0 | AN5: 32.70972 | AO5: 31129.439 | AP5: 115478.55 | AQ5: 7466.2976 | AR5: 3442.7125 | AS5: 3859.6273 | AT5: 247.772 | AU5: 4084.1238 | AV5: 5.5752 | AW5: 26.37448 | AX5: 122.42539 | AY5: 17931.902 | AZ5: 3278.5344 | BA5: 0 | BB5: 0 | BC5: 1227.544 | BD5: 24.96537 | BE5: 4825.6174 | BF5: 1438.0797 | BG5: 774.30697 | BH5: 32.90939 | BI5: 1208.5972 | BJ5: 2660.0249 | BK5: 4237.5729 | BL5: 10504.286 | BM5: 20002.065 | BN5: 9530.5506 | BO5: 2108.9683 | BP5: 400.6016 | BQ5: 2.15351 | BR5: 4.60138 | BS5: 3174.7323 | BT5: 6588.9122 | BU5: 11037.188 | BV5: 203219.03 | BW5: 54276.676 | BX5: 18792.897 | BY5: 12820.904 | BZ5: 7.02996 | CA5: 23985.909 | CB5: 562.53789 | CC5: 48.19818 | CD5: 0.011 | CE5: 144.23965 | CF5: 4276.7002 | CG5: 2338.1597 | CH5: 30463.273 | CI5: 40494.759 | CJ5: 28.47 | CK5: 39026.89 | CL5: 7926.7196 | CM5: 731.278 | CN5: 6510.3774 | CO5: 53.39901 | CP5: 219.99625 | CQ5: 92.032 | CR5: 11034.146 | CS5: 1356.8451 | CT5: 8670.7026 | CU5: 360.91503 | CV5: 569.80631 | CW5: 2439035.6 | CX5: 2439035.6
A6: 2020 | B6: =ROUNDUP(MONTH($B6)/3, 0) -> 2 | C6: 43922 | D6: 7636.5775 | E6: 11334.171 | F6: 10272.063 | G6: 1033.8918 | H6: 2567.3537 | I6: 107589.82 | J6: 1815.8753 | K6: 90541.925 | L6: 157384.05 | M6: 9.10763 | N6: 8167.5797 | O6: 1872.0622 | P6: 363.0955 | Q6: 44.27424 | R6: 59569.307 | S6: 3613.91 | T6: 34592.498 | U6: 8175.3612 | V6: 12455.963 | W6: 6678.2493 | X6: 33625.343 | Y6: 2408.0981 | Z6: 3412.9711 | AA6: 1215.514 | AB6: 843.94455 | AC6: 2274.7494 | AD6: 701773.55 | AE6: 7591.4636 | AF6: 8069.9645 | AG6: 29251.21 | AH6: 3000.1722 | AI6: 4835.5166 | AJ6: 24231.095 | AK6: 12748.492 | AL6: 5925.1496 | AM6: 0 | AN6: 4.46485 | AO6: 25015.153 | AP6: 116495.32 | AQ6: 2638.9385 | AR6: 1111.7788 | AS6: 1500.1158 | AT6: 44.66694 | AU6: 3989.1284 | AV6: 0 | AW6: 5.5066 | AX6: 32.83954 | AY6: 13464.055 | AZ6: 735.65476 | BA6: 0 | BB6: 0 | BC6: 25.64096 | BD6: 24.24775 | BE6: 2405.8986 | BF6: 164.78519 | BG6: 341.15757 | BH6: 10.14846 | BI6: 337.6931 | BJ6: 1197.161 | BK6: 244.97228 | BL6: 2783.7943 | BM6: 4543.8581 | BN6: 5440.7928 | BO6: 1262.4193 | BP6: 198.34159 | BQ6: 9.841 | BR6: 4.4118 | BS6: 910.21525 | BT6: 2784.7525 | BU6: 8370.059 | BV6: 125274.17 | BW6: 44387.647 | BX6: 4537.4859 | BY6: 10573.852 | BZ6: 0.00594 | CA6: 21766.629 | CB6: 357.56607 | CC6: 2.4368 | CD6: 0 | CE6: 24.156 | CF6: 2109.9722 | CG6: 692.27791 | CH6: 14529.542 | CI6: 17970.01 | CJ6: 0 | CK6: 25841.878 | CL6: 1555.7069 | CM6: 9.466 | CN6: 7105.7616 | CO6: 22.78843 | CP6: 0 | CQ6: 5078 | CR6: 4081.2456 | CS6: 2213.7177 | CT6: 11850.708 | CU6: 930.873 | CV6: 300.75876 | CW6: 1864238.8 | CX6: 1864238.8
A7: 2020 | B7: =ROUNDUP(MONTH($B7)/3, 0) -> 2 | C7: 43952 | D7: 12423.199 | E7: 8739.1907 | F7: 7760.6506 | G7: 1420.3196 | H7: 2295.117 | I7: 146473.07 | J7: 1827.1337 | K7: 101953.32 | L7: 141864.02 | M7: 1613.5924 | N7: 4326.4447 | O7: 2784.706 | P7: 691.47952 | Q7: 18.19796 | R7: 77606.506 | S7: 2405.0459 | T7: 31593.03 | U7: 9986.3881 | V7: 13662.819 | W7: 6915.1673 | X7: 30329.982 | Y7: 1384.2941 | Z7: 2926.7982 | AA7: 803.55958 | AB7: 625.58304 | AC7: 11741.155 | AD7: 928404.78 | AE7: 4828.6107 | AF7: 7867.3875 | AG7: 29397.877 | AH7: 3145.1364 | AI7: 4636.9098 | AJ7: 27472.352 | AK7: 18133.411 | AL7: 3788.9266 | AM7: 0 | AN7: 0 | AO7: 38475.648 | AP7: 84818.214 | AQ7: 3401.4931 | AR7: 837.66025 | AS7: 1837.1784 | AT7: 129.9768 | AU7: 1894.0616 | AV7: 8.02385 | AW7: 16.66733 | AX7: 1064.5958 | AY7: 22432.234 | AZ7: 878.1678 | BA7: 0 | BB7: 0 | BC7: 257.35696 | BD7: 23.50955 | BE7: 2300.4321 | BF7: 897.40533 | BG7: 902.1713 | BH7: 10.32645 | BI7: 441.36278 | BJ7: 1896.7769 | BK7: 633.69167 | BL7: 5047.3628 | BM7: 5390.8963 | BN7: 9293.0801 | BO7: 624.06844 | BP7: 288.64207 | BQ7: 18.48622 | BR7: 0.594 | BS7: 1341.921 | BT7: 1691.8232 | BU7: 11179.301 | BV7: 225502.27 | BW7: 32567.331 | BX7: 5560.2636 | BY7: 5754.4293 | BZ7: 12.00632 | CA7: 27795.905 | CB7: 70.64954 | CC7: 2.45844 | CD7: 0 | CE7: 29.11532 | CF7: 2424.5801 | CG7: 1125.6992 | CH7: 14249.035 | CI7: 27941.728 | CJ7: 219.264 | CK7: 4635.2617 | CL7: 1732.9183 | CM7: 166.10809 | CN7: 6822.7751 | CO7: 61.71479 | CP7: 29.83527 | CQ7: 265.7017 | CR7: 4787.7206 | CS7: 116.16534 | CT7: 9080.0985 | CU7: 135.526 | CV7: 203.64973 | CW7: 2221171.5 | CX7: 2221171.5
A8: 2020 | B8: =ROUNDUP(MONTH($B8)/3, 0) -> 2 | C8: 43983 | D8: 20679.381 | E8: 6372.6097 | F8: 9267.5178 | G8: 1211.9578 | H8: 3161.6928 | I8: 100946.03 | J8: 1537.4502 | K8: 95216.851 | L8: 194805.85 | M8: 752.15871 | N8: 8026.7694 | O8: 3119.1465 | P8: 220.98755 | Q8: 27.36 | R8: 73167.068 | S8: 1548.3924 | T8: 28866.329 | U8: 5285.9972 | V8: 13302.361 | W8: 6843.2821 | X8: 31288.539 | Y8: 2409.5887 | Z8: 2736.0624 | AA8: 2600.9276 | AB8: 949.24465 | AC8: 2225.9328 | AD8: 921343.93 | AE8: 6378.0183 | AF8: 6824.3384 | AG8: 32996.846 | AH8: 3110.0255 | AI8: 5711.8739 | AJ8: 29741.566 | AK8: 13070.226 | AL8: 4845.322 | AM8: 0 | AN8: 56.75789 | AO8: 33506.747 | AP8: 78733.453 | AQ8: 5960.9231 | AR8: 1383.3954 | AS8: 2915.6486 | AT8: 356.43617 | AU8: 1915.1214 | AV8: 0 | AW8: 9.09624 | AX8: 562.99207 | AY8: 21125.981 | AZ8: 2067.5807 | BA8: 0 | BB8: 0.17081 | BC8: 210.34275 | BD8: 68.59759 | BE8: 2868.6449 | BF8: 498.69251 | BG8: 555.94538 | BH8: 39.94354 | BI8: 644.85967 | BJ8: 2576.4763 | BK8: 1165.4057 | BL8: 7819.0367 | BM8: 13128.582 | BN8: 8040.4766 | BO8: 908.47722 | BP8: 706.24604 | BQ8: 0.8842 | BR8: 7.817 | BS8: 2631.7251 | BT8: 3451.7717 | BU8: 8694.1881 | BV8: 247568.94 | BW8: 35879.478 | BX8: 7388.9622 | BY8: 8458.9053 | BZ8: 3.79233 | CA8: 27369.887 | CB8: 498.85748 | CC8: 0 | CD8: 0 | CE8: 0 | CF8: 3503.6078 | CG8: 1726.2529 | CH8: 21462.239 | CI8: 41720.08 | CJ8: 39.0122 | CK8: 23561.033 | CL8: 1110.2288 | CM8: 84.27767 | CN8: 6715.9794 | CO8: 557.01176 | CP8: 0 | CQ8: 64.98823 | CR8: 8234.1387 | CS8: 309.99266 | CT8: 9716.4864 | CU8: 2.3 | CV8: 301.57871 | CW8: 2289482.1 | CX8: 2289482.1
A9: 2020 | B9: =ROUNDUP(MONTH($B9)/3, 0) -> 3 | C9: 44013 | D9: 3462.8314 | E9: 8003.0681 | F9: 13227.402 | G9: 1060.0127 | H9: 2792.4633 | I9: 107332.64 | J9: 1722.265 | K9: 91828.713 | L9: 270277.39 | M9: 598.65566 | N9: 10609.526 | O9: 2401.5718 | P9: 1080.1327 | Q9: 55.03872 | R9: 46343.557 | S9: 4646.7644 | T9: 44149.23 | U9: 8982.3554 | V9: 16069.36 | W9: 9458.2393 | X9: 35857.526 | Y9: 2771.5441 | Z9: 3143.1626 | AA9: 2261.8491 | AB9: 1726.7204 | AC9: 22934.87 | AD9: 936559.69 | AE9: 5837.8874 | AF9: 7522.937 | AG9: 32300.99 | AH9: 5842.7649 | AI9: 7270.2102 | AJ9: 34178.811 | AK9: 16649.27 | AL9: 3996.4515 | AM9: 1.42611 | AN9: 4.8685 | AO9: 46943.579 | AP9: 113001.52 | AQ9: 8842.172 | AR9: 1145.8388 | AS9: 3603.8111 | AT9: 531.8411 | AU9: 2857.0435 | AV9: 15.1052 | AW9: 58.3406 | AX9: 193.97437 | AY9: 24337.799 | AZ9: 2411.9137 | BA9: 0 | BB9: 0.025 | BC9: 386.66372 | BD9: 67.9381 | BE9: 3168.7751 | BF9: 784.05653 | BG9: 1021.9391 | BH9: 66.39818 | BI9: 616.07914 | BJ9: 2642.3285 | BK9: 3010.3127 | BL9: 9087.1263 | BM9: 15819.586 | BN9: 9578.8974 | BO9: 1438.3002 | BP9: 508.00818 | BQ9: 13.75244 | BR9: 9.581 | BS9: 3398.6351 | BT9: 5037.855 | BU9: 11581.019 | BV9: 291202.74 | BW9: 32654.022 | BX9: 11628.994 | BY9: 16587.877 | BZ9: 0.82727 | CA9: 28380.911 | CB9: 573.37866 | CC9: 23.5925 | CD9: 17.07191 | CE9: 157.70372 | CF9: 5201.7083 | CG9: 2301.4357 | CH9: 24557.622 | CI9: 39518.204 | CJ9: 6.1152 | CK9: 36713.524 | CL9: 1926.7839 | CM9: 93.095 | CN9: 7993.5277 | CO9: 110.67312 | CP9: 6.522 | CQ9: 28.9568 | CR9: 6909.2677 | CS9: 1199.2987 | CT9: 8519.1336 | CU9: 0.474 | CV9: 532.41455 | CW9: 2551988.3 | CX9: 2551988.3
A10: 2020 | B10: =ROUNDUP(MONTH($B10)/3, 0) -> 3 | C10: 44044 | D10: 19307.744 | E10: 9069.8061 | F10: 9065.1832 | G10: 1397.4092 | H10: 2587.3571 | I10: 93201.056 | J10: 1674.3694 | K10: 78973.677 | L10: 201786.85 | M10: 178.59874 | N10: 7177.2354 | O10: 1710.133 | P10: 726.66451 | Q10: 14.64 | R10: 48286.822 | S10: 3629.7212 | T10: 42992.298 | U10: 11807.748 | V10: 13359.498 | W10: 8616.5724 | X10: 33037.785 | Y10: 1566.4694 | Z10: 2491.7716 | AA10: 691.00058 | AB10: 1226.6447 | AC10: 2147.7141 | AD10: 1103433.3 | AE10: 6259.649 | AF10: 8736.0522 | AG10: 33823.501 | AH10: 5149.8577 | AI10: 7010.2198 | AJ10: 35480.435 | AK10: 17598.248 | AL10: 3769.0606 | AM10: 0 | AN10: 13.1366 | AO10: 33612.421 | AP10: 106562.53 | AQ10: 7941.4426 | AR10: 2016.8387 | AS10: 3559.2674 | AT10: 541.35067 | AU10: 3628.2314 | AV10: 0.1799 | AW10: 25.89096 | AX10: 297.71655 | AY10: 17781.011 | AZ10: 1649.9764 | BA10: 0 | BB10: 0 | BC10: 181.4757 | BD10: 51.84467 | BE10: 4525.0127 | BF10: 1328.9749 | BG10: 1021.7314 | BH10: 149.81703 | BI10: 887.44201 | BJ10: 2471.0874 | BK10: 3823.8965 | BL10: 12569.863 | BM10: 18452.812 | BN10: 9571.916 | BO10: 1444.4104 | BP10: 220.51369 | BQ10: 39.97421 | BR10: 0.945 | BS10: 3641.1238 | BT10: 7268.9126 | BU10: 10088.61 | BV10: 287292.99 | BW10: 44967.362 | BX10: 8721.334 | BY10: 9598.1892 | BZ10: 5.8698 | CA10: 24346.887 | CB10: 442.07224 | CC10: 20.08335 | CD10: 0 | CE10: 24.565 | CF10: 4498.8126 | CG10: 2266.3248 | CH10: 30672.649 | CI10: 43712.636 | CJ10: 3.72288 | CK10: 24714.622 | CL10: 1612.0636 | CM10: 206.264 | CN10: 7134.6964 | CO10: 120.77534 | CP10: 5.25225 | CQ10: 0 | CR10: 9496.1421 | CS10: 1115.4602 | CT10: 9341.83 | CU10: 148.19317 | CV10: 942.46717 | CW10: 2584766.8 | CX10: 2584766.8
A11: 2020 | B11: =ROUNDUP(MONTH($B11)/3, 0) -> 3 | C11: 44075 | D11: 5328.0891 | E11: 12127.899 | F11: 14334.331 | G11: 1196.3876 | H11: 3292.3668 | I11: 108948.9 | J11: 1730.5213 | K11: 86821.613 | L11: 217897.43 | M11: 14.14866 | N11: 8095.4897 | O11: 2129.5422 | P11: 114.60412 | Q11: 14.61542 | R11: 34311.53 | S11: 3445.0166 | T11: 53438.732 | U11: 9204.3988 | V11: 15094.125 | W11: 9228.5458 | X11: 37043.65 | Y11: 4122.11 | Z11: 2740.2882 | AA11: 345.016 | AB11: 1795.4164 | AC11: 1743.122 | AD11: 931901.67 | AE11: 5215.6114 | AF11: 6635.7382 | AG11: 33616.144 | AH11: 4721.9778 | AI11: 8033.5231 | AJ11: 40503.899 | AK11: 15584.054 | AL11: 4935.7139 | AM11: 3.932 | AN11: 60.42866 | AO11: 46851.074 | AP11: 126820.73 | AQ11: 8124.4356 | AR11: 3742.9268 | AS11: 3901.3047 | AT11: 419.6996 | AU11: 4125.8767 | AV11: 11.79234 | AW11: 4.54522 | AX11: 125.04524 | AY11: 21018.435 | AZ11: 2522.3941 | BA11: 0 | BB11: 2.87525 | BC11: 858.94689 | BD11: 141.8152 | BE11: 3811.6069 | BF11: 831.24142 | BG11: 1263.0381 | BH11: 37.82256 | BI11: 903.16993 | BJ11: 2275.561 | BK11: 4726.8272 | BL11: 10445.939 | BM11: 15710.139 | BN11: 8893.3258 | BO11: 1851.8581 | BP11: 644.5217 | BQ11: 78.55739 | BR11: 4.67457 | BS11: 3977.6395 | BT11: 6090.8854 | BU11: 11970.605 | BV11: 298528.68 | BW11: 38100.985 | BX11: 10914.616 | BY11: 13701.53 | BZ11: 14.01775 | CA11: 27967.044 | CB11: 1523.1041 | CC11: 25.79591 | CD11: 9.65826 | CE11: 231.38383 | CF11: 5876.2768 | CG11: 3100.2285 | CH11: 39417.453 | CI11: 59468.836 | CJ11: 232.2091 | CK11: 32213.334 | CL11: 4319.5195 | CM11: 185.096 | CN11: 6579.5672 | CO11: 96.2227 | CP11: 6.57484 | CQ11: 0 | CR11: 10368.027 | CS11: 1230.3817 | CT11: 11238.754 | CU11: 669.04391 | CV11: 895.37942 | CW11: 2544873.6 | CX11: 2544873.6
A12: 2020 | B12: =ROUNDUP(MONTH($B12)/3, 0) -> 4 | C12: 44105 | D12: 20199.379 | E12: 13383.581 | F12: 9802.6584 | G12: 1615.7324 | H12: 3409.8577 | I12: 101595.86 | J12: 2234.002 | K12: 116055.25 | L12: 173371.85 | M12: 3.80323 | N12: 7618.092 | O12: 4352.7958 | P12: 291.98392 | Q12: 29.91293 | R12: 48942.226 | S12: 2866.4332 | T12: 54238.004 | U12: 9420.1782 | V12: 11635.229 | W12: 9072.5215 | X12: 33705.384 | Y12: 2142.3544 | Z12: 2438.6455 | AA12: 996.44258 | AB12: 1392.8087 | AC12: 17998.639 | AD12: 969246.64 | AE12: 8979.0802 | AF12: 8862.3294 | AG12: 32437.104 | AH12: 3974.7049 | AI12: 7213.2521 | AJ12: 39654.601 | AK12: 11075.233 | AL12: 4275.4118 | AM12: 0 | AN12: 70.51468 | AO12: 43601.579 | AP12: 101781.69 | AQ12: 8372.2972 | AR12: 2892.8009 | AS12: 3427.5338 | AT12: 220.84417 | AU12: 4596.919 | AV12: 12.54245 | AW12: 10.51317 | AX12: 116.01949 | AY12: 22336.759 | AZ12: 2336.2322 | BA12: 1.426 | BB12: 0.3872 | BC12: 558.99209 | BD12: 63.05937 | BE12: 4542.6882 | BF12: 724.01227 | BG12: 1340.3991 | BH12: 58.10527 | BI12: 940.19936 | BJ12: 2795.6299 | BK12: 3692.3818 | BL12: 13150.312 | BM12: 20696.395 | BN12: 6000.6068 | BO12: 1762.0192 | BP12: 488.54595 | BQ12: 54.55435 | BR12: 33.20294 | BS12: 4167.1942 | BT12: 6194.0816 | BU12: 10250.068 | BV12: 378452.1 | BW12: 44892.123 | BX12: 13292.74 | BY12: 16649.751 | BZ12: 27.32535 | CA12: 29222.435 | CB12: 530.7292 | CC12: 47.50697 | CD12: 10.52226 | CE12: 86.87396 | CF12: 5529.053 | CG12: 2340.027 | CH12: 35965.498 | CI12: 56209.662 | CJ12: 200.50294 | CK12: 24834.522 | CL12: 1618.601 | CM12: 181.90585 | CN12: 7856.2383 | CO12: 8.87077 | CP12: 0.38926 | CQ12: 2170.8755 | CR12: 9373.3803 | CS12: 1674.8408 | CT12: 11062.019 | CU12: 221.025 | CV12: 671.49301 | CW12: 2644953.5 | CX12: 2644953.5
A13: 2020 | B13: =ROUNDUP(MONTH($B13)/3, 0) -> 4 | C13: 44136 | D13: 11434.976 | E13: 12689.547 | F13: 17127.983 | G13: 2367.8987 | H13: 3059.5521 | I13: 125965.22 | J13: 2300.9295 | K13: 105597.31 | L13: 227635.81 | M13: 103.29748 | N13: 6559.8745 | O13: 2711.4873 | P13: 210.76136 | Q13: 45.52654 | R13: 42342.796 | S13: 2332.2197 | T13: 46964.819 | U13: 9476.8659 | V13: 12698.756 | W13: 8547.4817 | X13: 29579.604 | Y13: 4036.2958 | Z13: 2414.5017 | AA13: 2494.8859 | AB13: 1379.3152 | AC13: 415.04937 | AD13: 872364.36 | AE13: 8695.9553 | AF13: 8844.3592 | AG13: 27072.153 | AH13: 3521.1182 | AI13: 7749.6485 | AJ13: 40168.27 | AK13: 13522.696 | AL13: 4593.1318 | AM13: 1.17527 | AN13: 0.41946 | AO13: 32413.162 | AP13: 114105.92 | AQ13: 7509.7285 | AR13: 3140.4753 | AS13: 3890.0713 | AT13: 811.48058 | AU13: 3895.8459 | AV13: 4.52443 | AW13: 54.95668 | AX13: 154.62726 | AY13: 21046.03 | AZ13: 2474.816 | BA13: 0 | BB13: 0.308 | BC13: 1054.1781 | BD13: 133.39842 | BE13: 4999.3548 | BF13: 709.23644 | BG13: 1345.9202 | BH13: 109.98537 | BI13: 1130.7437 | BJ13: 2324.315 | BK13: 5528.7195 | BL13: 15238.304 | BM13: 23935.551 | BN13: 7597.9979 | BO13: 2053.5054 | BP13: 518.17182 | BQ13: 64.28021 | BR13: 5.14633 | BS13: 4313.4942 | BT13: 5862.8343 | BU13: 12887.151 | BV13: 298377.68 | BW13: 46651.96 | BX13: 12819.122 | BY13: 12943.418 | BZ13: 8.39972 | CA13: 34693.722 | CB13: 407.93503 | CC13: 28.11501 | CD13: 10.48685 | CE13: 104.71741 | CF13: 5509.7053 | CG13: 3249.9363 | CH13: 33628.241 | CI13: 54030.605 | CJ13: 11.3225 | CK13: 39441.843 | CL13: 2226.8522 | CM13: 282.71055 | CN13: 7848.9929 | CO13: 93.91285 | CP13: 221.89604 | CQ13: 4.93615 | CR13: 10280.908 | CS13: 1774.4079 | CT13: 11161.148 | CU13: 17.20748 | CV13: 1201.4068 | CW13: 2523371.9 | CX13: 2523371.9
A14: 2020 | B14: =ROUNDUP(MONTH($B14)/3, 0) -> 4 | C14: 44166 | D14: 18731.893 | E14: 18498.074 | F14: 8689.1018 | G14: 3092.9563 | H14: 2849.0581 | I14: 106377.55 | J14: 2241.9835 | K14: 172723.44 | L14: 316675.7 | M14: 94.44846 | N14: 3793.1528 | O14: 3309.4849 | P14: 1148.4113 | Q14: 95.30487 | R14: 35751.706 | S14: 3147.1054 | T14: 49451.686 | U14: 9597.2711 | V14: 13657.975 | W14: 8113.947 | X14: 37966.196 | Y14: 4735.4571 | Z14: 3161.1475 | AA14: 2850.4502 | AB14: 1855.0056 | AC14: 6296.006 | AD14: 1092089.4 | AE14: 8599.1426 | AF14: 10801.978 | AG14: 32438.039 | AH14: 5857.629 | AI14: 8454.7189 | AJ14: 40785.754 | AK14: 14279.076 | AL14: 3861.8301 | AM14: 0 | AN14: 22.96484 | AO14: 45485.199 | AP14: 147538.74 | AQ14: 10170.413 | AR14: 3516.4679 | AS14: 4899.0343 | AT14: 763.0953 | AU14: 4618.7441 | AV14: 3.68824 | AW14: 75.41764 | AX14: 191.77426 | AY14: 25227.387 | AZ14: 2467.3389 | BA14: 0 | BB14: 0 | BC14: 970.4037 | BD14: 79.49654 | BE14: 3908.7511 | BF14: 593.48646 | BG14: 1495.0019 | BH14: 36.78806 | BI14: 1394.0852 | BJ14: 3093.7801 | BK14: 3201.6957 | BL14: 16164.95 | BM14: 24209.966 | BN14: 7817.6666 | BO14: 2180.1917 | BP14: 921.06093 | BQ14: 19.03901 | BR14: 12.02943 | BS14: 4594.4342 | BT14: 9228.0256 | BU14: 15446.757 | BV14: 331767.39 | BW14: 55403.827 | BX14: 13288.182 | BY14: 18563.397 | BZ14: 0.87861 | CA14: 30643.849 | CB14: 426.50916 | CC14: 10.08816 | CD14: 2.16388 | CE14: 156.07275 | CF14: 6294.7762 | CG14: 3143.7349 | CH14: 49676.061 | CI14: 53109.598 | CJ14: 107.41517 | CK14: 38938.324 | CL14: 697.54595 | CM14: 1043.8098 | CN14: 7324.9103 | CO14: 109.57466 | CP14: 12.14242 | CQ14: 771.04103 | CR14: 10446.705 | CS14: 1934.9288 | CT14: 11320.846 | CU14: 388.332 | CV14: 835.17413 | CW14: 3028837.2 | CX14: 3028837.2
A15: =YEAR($B15) -> 2021 | B15: =ROUNDUP(MONTH($B15)/3, 0) -> 1 | C15: 44197 | D15: 13911.225 | E15: 12741.043 | F15: 8186.087 | G15: 1891.9865 | H15: 3323.4998 | I15: 130252.4 | J15: 2121.0343 | K15: 104670.6 | L15: 255455.19 | M15: 8.616 | N15: 5722.5441 | O15: 3421.7549 | P15: 178.35035 | Q15: 24.11941 | R15: 25449.877 | S15: 1466.8528 | T15: 32402.132 | U15: 7130.2707 | V15: 8207.6304 | W15: 7073.8667 | X15: 25894.914 | Y15: 2729.6787 | Z15: 2222.3064 | AA15: 1065.1418 | AB15: 1346.7871 | AC15: 1216.829 | AD15: 1182946.7 | AE15: 7957.9687 | AF15: 7984.621 | AG15: 22737.487 | AH15: 3456.1987 | AI15: 5478.1774 | AJ15: 28107.161 | AK15: 11349.955 | AL15: 3423.8799 | AM15: 0 | AN15: 3.34805 | AO15: 42420.967 | AP15: 130770.46 | AQ15: 6729.9684 | AR15: 3127.2572 | AS15: 2325.3111 | AT15: 214.5686 | AU15: 4474.3094 | AV15: 0 | AW15: 8.89161 | AX15: 13.24423 | AY15: 19722.687 | AZ15: 1630.5683 | BA15: 0 | BB15: 0 | BC15: 1005.0161 | BD15: 55.16542 | BE15: 3419.7832 | BF15: 585.19504 | BG15: 712.41378 | BH15: 59.59544 | BI15: 673.0778 | BJ15: 2590.6476 | BK15: 2464.5573 | BL15: 12374.742 | BM15: 15548.679 | BN15: 7110.0383 | BO15: 1158.98 | BP15: 574.49915 | BQ15: 6.67479 | BR15: 0 | BS15: 3739.8368 | BT15: 3626.4941 | BU15: 10494.509 | BV15: 191099.61 | BW15: 36932.943 | BX15: 11468.949 | BY15: 20863.128 | BZ15: 4.73823 | CA15: 29790.564 | CB15: 472.39478 | CC15: 33.57771 | CD15: 10.648 | CE15: 97.0421 | CF15: 3853.9803 | CG15: 2988.9177 | CH15: 28140.863 | CI15: 35554.166 | CJ15: 7.33472 | CK15: 13917.296 | CL15: 1108.1801 | CM15: 32.634 | CN15: 5990.0339 | CO15: 114.03802 | CP15: 1.794 | CQ15: 21.33 | CR15: 8147.4061 | CS15: 1587.5088 | CT15: 8527.2086 | CU15: 59.115 | CV15: 912.61658 | CW15: 2610936.4 | CX15: 2610936.4
A16: =YEAR($B16) -> 2021 | B16: =ROUNDUP(MONTH($B16)/3, 0) -> 1 | C16: 44228 | D16: 15034.396 | E16: 20707.191 | F16: 10782.322 | G16: 1506.7452 | H16: 3992.7001 | I16: 154414.6 | J16: 1960.6725 | K16: 93982.401 | L16: 267999.83 | M16: 185.02897 | N16: 3272.0664 | O16: 2362.8002 | P16: 271.41843 | Q16: 24.71142 | R16: 39288.292 | S16: 1461.23 | T16: 39991.037 | U16: 9210.0935 | V16: 13714.95 | W16: 9355.5469 | X16: 36236.339 | Y16: 2750.1877 | Z16: 3515.5831 | AA16: 284.89469 | AB16: 1645.2511 | AC16: 20083.241 | AD16: 1252154.3 | AE16: 6539.9314 | AF16: 9266.9378 | AG16: 32804.088 | AH16: 3941.2876 | AI16: 8999.9937 | AJ16: 37132.385 | AK16: 15684.013 | AL16: 5521.6506 | AM16: 0 | AN16: 31.71977 | AO16: 29976.551 | AP16: 159060.52 | AQ16: 7635.1124 | AR16: 5152.6784 | AS16: 3534.7149 | AT16: 437.67698 | AU16: 4581.9621 | AV16: 10.5825 | AW16: 62.04493 | AX16: 128.33005 | AY16: 18174.763 | AZ16: 2417.687 | BA16: 0 | BB16: 0 | BC16: 1019.2704 | BD16: 232.19459 | BE16: 4045.4395 | BF16: 797.46989 | BG16: 1234.6013 | BH16: 46.87234 | BI16: 952.68809 | BJ16: 2767.0733 | BK16: 3562.2068 | BL16: 13411.063 | BM16: 19332.57 | BN16: 4691.9404 | BO16: 2146.7511 | BP16: 613.15255 | BQ16: 3.05123 | BR16: 3.20544 | BS16: 5035.3128 | BT16: 6421.3744 | BU16: 12479.737 | BV16: 261144.81 | BW16: 31513.479 | BX16: 13653.655 | BY16: 16420.65 | BZ16: 1.16262 | CA16: 34815.77 | CB16: 411.17659 | CC16: 34.02049 | CD16: 2.62544 | CE16: 63.04497 | CF16: 5584.8127 | CG16: 2996.0559 | CH16: 33554.953 | CI16: 43486.227 | CJ16: 61.00036 | CK16: 20877.374 | CL16: 2183.341 | CM16: 124.44095 | CN16: 7415.5084 | CO16: 135.4824 | CP16: 0 | CQ16: 0.095 | CR16: 12416.108 | CS16: 2549.5041 | CT16: 12099.206 | CU16: 611.19026 | CV16: 760.01858 | CW16: 2938994.1 | CX16: 2938994.1
A17: =YEAR($B17) -> 2021 | B17: =ROUNDUP(MONTH($B17)/3, 0) -> 1 | C17: 44256 | D17: 29470.398 | E17: 20817.408 | F17: 8220.3561 | G17: 2808.6078 | H17: 3754.6105 | I17: 204659.83 | J17: 2566.0262 | K17: 147978.95 | L17: 278224.94 | M17: 1042.5165 | N17: 6402.7726 | O17: 4153.2777 | P17: 1090.3993 | Q17: 65.40321 | R17: 72334.228 | S17: 941.33656 | T17: 54102.918 | U17: 10681.577 | V17: 16281.978 | W17: 10682.154 | X17: 37894.873 | Y17: 3494.4762 | Z17: 4065.5428 | AA17: 4503.0876 | AB17: 1828.431 | AC17: 21116.19 | AD17: 1399605.3 | AE17: 8192.7657 | AF17: 10069.704 | AG17: 30552.389 | AH17: 6125.8823 | AI17: 8029.9868 | AJ17: 43708.143 | AK17: 16178.032 | AL17: 4228.9153 | AM17: 0 | AN17: 4.25687 | AO17: 42013.551 | AP17: 150113.3 | AQ17: 8672.0825 | AR17: 5097.0415 | AS17: 4891.9746 | AT17: 504.11504 | AU17: 5489.8831 | AV17: 1.75295 | AW17: 99.73325 | AX17: 42.27037 | AY17: 24292.125 | AZ17: 2376.992 | BA17: 0 | BB17: 0.69336 | BC17: 1333.9815 | BD17: 295.97396 | BE17: 5026.3458 | BF17: 713.44617 | BG17: 1385.2707 | BH17: 212.78295 | BI17: 1602.3506 | BJ17: 3083.1161 | BK17: 3840.4882 | BL17: 16666.658 | BM17: 24651.798 | BN17: 10176.418 | BO17: 2434.1723 | BP17: 624.02884 | BQ17: 46.39415 | BR17: 7.06 | BS17: 3998.4424 | BT17: 7928.0548 | BU17: 13513.368 | BV17: 279537 | BW17: 35166.377 | BX17: 18627.106 | BY17: 23951.82 | BZ17: 0.87338 | CA17: 41515.611 | CB17: 780.21748 | CC17: 24.57989 | CD17: 10.40122 | CE17: 92.04335 | CF17: 6980.1346 | CG17: 4189.188 | CH17: 37012.958 | CI17: 54884.442 | CJ17: 68.7682 | CK17: 28651.729 | CL17: 2097.5215 | CM17: 813.7623 | CN17: 7849.823 | CO17: 214.91655 | CP17: 1.4352 | CQ17: 1204.1963 | CR17: 9740.1724 | CS17: 2907.6159 | CT17: 9026.5339 | CU17: 521.277 | CV17: 670.2894 | CW17: 3383554.1 | CX17: 3383554.1
A18: =YEAR($B18) -> 2021 | B18: =ROUNDUP(MONTH($B18)/3, 0) -> 2 | C18: 44287 | D18: 14569.425 | E18: 17686.102 | F18: 13186.095 | G18: 3642.8197 | H18: 3659.8691 | I18: 147307.18 | J18: 2763.3516 | K18: 129717.14 | L18: 243363.43 | M18: 1190.8728 | N18: 5872.5744 | O18: 3535.9929 | P18: 499.50416 | Q18: 113.19439 | R18: 67089.74 | S18: 2281.9681 | T18: 40652.568 | U18: 10360.073 | V18: 11475.497 | W18: 10061.091 | X18: 36101.172 | Y18: 2825.6409 | Z18: 3134.8555 | AA18: 685.6413 | AB18: 1939.638 | AC18: 3461.2628 | AD18: 1203308.6 | AE18: 6631.0257 | AF18: 9984.7997 | AG18: 31165.811 | AH18: 3667.6508 | AI18: 10156.703 | AJ18: 38888.289 | AK18: 15541.54 | AL18: 4290.4601 | AM18: 64.20827 | AN18: 43.27812 | AO18: 30786.856 | AP18: 167456.38 | AQ18: 8821.5383 | AR18: 6357.5696 | AS18: 3734.3199 | AT18: 704.20886 | AU18: 5946.0305 | AV18: 8.093 | AW18: 145.54578 | AX18: 132.16722 | AY18: 24023.731 | AZ18: 3465.2664 | BA18: 2.77344 | BB18: 0 | BC18: 1072.5362 | BD18: 248.19484 | BE18: 4775.3604 | BF18: 840.26437 | BG18: 1020.552 | BH18: 30.4849 | BI18: 1067.2748 | BJ18: 2988.7859 | BK18: 4050.5632 | BL18: 13373.781 | BM18: 22157.772 | BN18: 8508.6726 | BO18: 1920.6574 | BP18: 548.91255 | BQ18: 18.99573 | BR18: 1.325 | BS18: 4504.0157 | BT18: 6721.3714 | BU18: 13083.821 | BV18: 272004.22 | BW18: 34528.075 | BX18: 18096.524 | BY18: 18520.455 | BZ18: 0.05131 | CA18: 34011.197 | CB18: 898.1021 | CC18: 49.578 | CD18: 0 | CE18: 125.46468 | CF18: 5819.524 | CG18: 3976.6232 | CH18: 34811.062 | CI18: 52482.696 | CJ18: 49.27559 | CK18: 25739.418 | CL18: 1952.2247 | CM18: 567.688 | CN18: 6534.0832 | CO18: 278.02859 | CP18: 0 | CQ18: 697.45025 | CR18: 11740.7 | CS18: 2291.5342 | CT18: 11016.355 | CU18: 149.9815 | CV18: 595.16119 | CW18: 2976372.3 | CX18: 2976372.3
A19: =YEAR($B19) -> 2021 | B19: =ROUNDUP(MONTH($B19)/3, 0) -> 2 | C19: 44317 | D19: 9896.9705 | E19: 11920.867 | F19: 9325.8651 | G19: 2218.917 | H19: 4317.5893 | I19: 217431.35 | J19: 1704.6654 | K19: 128904.7 | L19: 124318.68 | M19: 719.18411 | N19: 8871.1202 | O19: 2516.199 | P19: 410.48461 | Q19: 9.74467 | R19: 84990.438 | S19: 2179.8639 | T19: 21403.408 | U19: 9860.5064 | V19: 6436.8228 | W19: 8959.6673 | X19: 20793.18 | Y19: 2137.9539 | Z19: 1720.5138 | AA19: 2262.5712 | AB19: 893.28869 | AC19: 6742.9018 | AD19: 1549776.4 | AE19: 8401.7882 | AF19: 9105.7644 | AG19: 21591.929 | AH19: 4912.3857 | AI19: 5769.4155 | AJ19: 23715.399 | AK19: 7547.3874 | AL19: 4193.7434 | AM19: 0 | AN19: 11.35772 | AO19: 39747.331 | AP19: 140940.67 | AQ19: 3638.6351 | AR19: 4764.2305 | AS19: 3902.4271 | AT19: 393.96065 | AU19: 4285.7028 | AV19: 1.1557 | AW19: 37.98328 | AX19: 77.66437 | AY19: 14313.209 | AZ19: 2415.5447 | BA19: 0 | BB19: 0.981 | BC19: 200.59388 | BD19: 210.95231 | BE19: 4319.2026 | BF19: 482.04872 | BG19: 948.83337 | BH19: 266.19917 | BI19: 737.58927 | BJ19: 2728.3696 | BK19: 1643.9057 | BL19: 12103.378 | BM19: 20522.609 | BN19: 6183.1541 | BO19: 1905.8776 | BP19: 302.26726 | BQ19: 3.47325 | BR19: 0 | BS19: 3140.3071 | BT19: 4546.3073 | BU19: 15655.345 | BV19: 302196.72 | BW19: 28484.883 | BX19: 11351.747 | BY19: 18312.046 | BZ19: 6.87009 | CA19: 36536.716 | CB19: 149.04497 | CC19: 8.01438 | CD19: 39.56467 | CE19: 91.57648 | CF19: 3178.0958 | CG19: 1875.5015 | CH19: 16262.65 | CI19: 23087.571 | CJ19: 61.98658 | CK19: 13917.02 | CL19: 4046.1032 | CM19: 166.552 | CN19: 5599.8974 | CO19: 37.3545 | CP19: 0 | CQ19: 757.33063 | CR19: 5510.9506 | CS19: 2170.316 | CT19: 6077.1415 | CU19: 71.609 | CV19: 523.1335 | CW19: 3096913.3 | CX19: 3096913.3
A20: =YEAR($B20) -> 2021 | B20: =ROUNDUP(MONTH($B20)/3, 0) -> 2 | C20: 44348 | D20: 5464.8101 | E20: 16091.965 | F20: 11380.108 | G20: 3069.7153 | H20: 3745.9008 | I20: 125897.16 | J20: 1463.8854 | K20: 125166.53 | L20: 115655.39 | M20: 35.53077 | N20: 9479.2041 | O20: 2618.0511 | P20: 88.36467 | Q20: 50.48794 | R20: 108183.33 | S20: 3658.2585 | T20: 16218.672 | U20: 9929.3562 | V20: 11795.818 | W20: 10057.239 | X20: 31341.313 | Y20: 3069.6076 | Z20: 2754.5234 | AA20: 1273.673 | AB20: 1335.6865 | AC20: 15853.588 | AD20: 1558797.1 | AE20: 5364.3329 | AF20: 8897.4544 | AG20: 30083.496 | AH20: 8073.0242 | AI20: 9014.3157 | AJ20: 33658.802 | AK20: 11327.484 | AL20: 4838.3568 | AM20: 0 | AN20: 31.15501 | AO20: 46416.391 | AP20: 165155.94 | AQ20: 5715.4284 | AR20: 5452.1217 | AS20: 3634.8385 | AT20: 743.33032 | AU20: 3760.0255 | AV20: 3.13995 | AW20: 50.76496 | AX20: 0 | AY20: 15909.532 | AZ20: 3419.6083 | BA20: 0 | BB20: 0.147 | BC20: 1123.4678 | BD20: 200.23165 | BE20: 5340.992 | BF20: 688.87312 | BG20: 1063.6078 | BH20: 35.87789 | BI20: 1202.3479 | BJ20: 3224.1762 | BK20: 5854.7536 | BL20: 15467.986 | BM20: 27651.05 | BN20: 7257.9436 | BO20: 2682.1331 | BP20: 976.28087 | BQ20: 4.57537 | BR20: 5.36396 | BS20: 4213.4008 | BT20: 6053.4255 | BU20: 10634.452 | BV20: 286289.56 | BW20: 42204.379 | BX20: 17574.137 | BY20: 18066.378 | BZ20: 1.28726 | CA20: 39477.091 | CB20: 110.05529 | CC20: 23.64262 | CD20: 1.76158 | CE20: 107.95515 | CF20: 5688.5184 | CG20: 3596.024 | CH20: 32142.464 | CI20: 37984.103 | CJ20: 6.26024 | CK20: 18033.123 | CL20: 1651.6962 | CM20: 2215.5874 | CN20: 6235.1428 | CO20: 135.41243 | CP20: 17.79847 | CQ20: 214.222 | CR20: 8884.0597 | CS20: 2144.0992 | CT20: 8629.5591 | CU20: 129.71 | CV20: 945.80091 | CW20: 3182215.7 | CX20: 3182215.7
A21: =YEAR($B21) -> 2021 | B21: =ROUNDUP(MONTH($B21)/3, 0) -> 3 | C21: 44378 | D21: 3719.3334 | E21: 21743.559 | F21: 9019.3801 | G21: 3075.9489 | H21: 4515.6599 | I21: 106769.88 | J21: 2294.71 | K21: 141759.41 | L21: 309123.08 | M21: 860.16755 | N21: 5996.3833 | O21: 3708.6236 | P21: 1041.0402 | Q21: 93.57512 | R21: 60008.458 | S21: 3284.058 | T21: 39668.284 | U21: 11528.138 | V21: 15746.605 | W21: 12118.647 | X21: 42953.738 | Y21: 4092.5355 | Z21: 5520.9043 | AA21: 397.92305 | AB21: 1378.608 | AC21: 25542.104 | AD21: 1415764.2 | AE21: 13958.959 | AF21: 10748.641 | AG21: 37372.744 | AH21: 5327.6347 | AI21: 9415.175 | AJ21: 47527.934 | AK21: 18366.914 | AL21: 4097.2085 | AM21: 31.18442 | AN21: 16.33865 | AO21: 45199.467 | AP21: 175121.41 | AQ21: 10604.133 | AR21: 5601.686 | AS21: 4837.1058 | AT21: 587.72725 | AU21: 3579.6379 | AV21: 29.05367 | AW21: 35.51878 | AX21: 274.63153 | AY21: 25854.969 | AZ21: 4023.9283 | BA21: 0 | BB21: 0 | BC21: 1095.5426 | BD21: 690.43605 | BE21: 5730.381 | BF21: 858.21668 | BG21: 1286.1304 | BH21: 452.76997 | BI21: 1091.3835 | BJ21: 3635.3101 | BK21: 6013.0904 | BL21: 17639.374 | BM21: 30113.524 | BN21: 6959.0585 | BO21: 2794.7721 | BP21: 1044.625 | BQ21: 204.26804 | BR21: 9.759 | BS21: 4366.15 | BT21: 9021.5138 | BU21: 12252.309 | BV21: 313275.83 | BW21: 50827.657 | BX21: 20078.453 | BY21: 37410.27 | BZ21: 0.11751 | CA21: 47202.285 | CB21: 570.37702 | CC21: 0.14036 | CD21: 29.69072 | CE21: 152.34662 | CF21: 6863.58 | CG21: 4706.7633 | CH21: 45806.557 | CI21: 54037.384 | CJ21: 7.46224 | CK21: 38035.937 | CL21: 2657.757 | CM21: 4691.9796 | CN21: 6200.8736 | CO21: 83.48062 | CP21: 4.14345 | CQ21: 12.645 | CR21: 14261.742 | CS21: 3437.5795 | CT21: 11980.341 | CU21: 643.14164 | CV21: 1583.7581 | CW21: 3444157.9 | CX21: 3444157.9
A22: =YEAR($B22) -> 2021 | B22: =ROUNDUP(MONTH($B22)/3, 0) -> 3 | C22: 44409 | D22: 6056.4972 | E22: 29048.512 | F22: 13332.208 | G22: 3233.0965 | H22: 4138.3266 | I22: 114586.3 | J22: 1347.7057 | K22: 97713.862 | L22: 322175.05 | M22: 446.43979 | N22: 4263.6649 | O22: 2882.2647 | P22: 272.80363 | Q22: 62.73402 | R22: 73838.053 | S22: 2706.922 | T22: 49091.771 | U22: 11666.64 | V22: 14434.547 | W22: 11488.113 | X22: 36089.849 | Y22: 3953.216 | Z22: 4837.8778 | AA22: 165.699 | AB22: 2160.4197 | AC22: 11450.434 | AD22: 1513093.1 | AE22: 10810.046 | AF22: 13039.103 | AG22: 38892.067 | AH22: 3542.8229 | AI22: 11870.652 | AJ22: 44079.981 | AK22: 16049.059 | AL22: 5347.0868 | AM22: 0.36595 | AN22: 44.9395 | AO22: 55621.149 | AP22: 176633.24 | AQ22: 8655.5986 | AR22: 8149.7284 | AS22: 4139.763 | AT22: 686.88757 | AU22: 3923.1501 | AV22: 5.8961 | AW22: 48.58111 | AX22: 148.31189 | AY22: 20941.421 | AZ22: 2446.211 | BA22: 0 | BB22: 0 | BC22: 1424.0869 | BD22: 268.06692 | BE22: 5874.0354 | BF22: 1250.7621 | BG22: 1104.4815 | BH22: 239.15478 | BI22: 1181.1656 | BJ22: 4057.487 | BK22: 6148.4613 | BL22: 15798.532 | BM22: 28104.076 | BN22: 7355.8209 | BO22: 3117.8351 | BP22: 1021.6078 | BQ22: 12.45716 | BR22: 3.04598 | BS22: 4412.095 | BT22: 7267.6478 | BU22: 19021.491 | BV22: 225795.94 | BW22: 49117.047 | BX22: 28577.014 | BY22: 26613.598 | BZ22: 131.58416 | CA22: 38184.047 | CB22: 739.25436 | CC22: 222.49211 | CD22: 0.7659 | CE22: 169.31054 | CF22: 6313.8852 | CG22: 4512.5518 | CH22: 40207.911 | CI22: 53682.171 | CJ22: 162.31276 | CK22: 47047.606 | CL22: 33303.516 | CM22: 2044.541 | CN22: 8695.4864 | CO22: 79.89765 | CP22: 1.965 | CQ22: 2381.7671 | CR22: 15943.514 | CS22: 2715.7558 | CT22: 9972.104 | CU22: 95.899 | CV22: 1156.5033 | CW22: 3465142.9 | CX22: 3465142.9
